Failure # 1 (occurred at 2020-05-09_10-57-45)
Traceback (most recent call last):
  File "/home/tom/.local/lib/python3.7/site-packages/ray/tune/trial_runner.py", line 467, in _process_trial
    result = self.trial_executor.fetch_result(trial)
  File "/home/tom/.local/lib/python3.7/site-packages/ray/tune/ray_trial_executor.py", line 381, in fetch_result
    result = ray.get(trial_future[0], DEFAULT_GET_TIMEOUT)
  File "/home/tom/.local/lib/python3.7/site-packages/ray/worker.py", line 1513, in get
    raise value.as_instanceof_cause()
ray.exceptions.RayTaskError(TuneError): [36mray::WrappedTrackFunc.train()[39m (pid=3330, ip=10.138.0.2)
  File "python/ray/_raylet.pyx", line 452, in ray._raylet.execute_task
  File "python/ray/_raylet.pyx", line 407, in ray._raylet.execute_task.function_executor
  File "/home/tom/.local/lib/python3.7/site-packages/ray/tune/trainable.py", line 261, in train
    result = self._train()
  File "/home/tom/.local/lib/python3.7/site-packages/ray/tune/function_runner.py", line 224, in _train
    ("Wrapped function ran until completion without reporting "
ray.tune.error.TuneError: Wrapped function ran until completion without reporting results or raising an exception.

